<?xml version="1.0" encoding="utf-8"?>
<!-- This URDF was automatically created by SolidWorks to URDF Exporter! Originally created by Stephen Brawner (brawner@gmail.com) 
     Commit Version: 1.6.0-1-g15f4949  Build Version: 1.6.7594.29634
     For more information, please see http://wiki.ros.org/sw_urdf_exporter -->
<robot
  name="bartender_description">
  <link
    name="base_link">
    <inertial>
      <origin
        xyz="-0.00061320673012466 0.000613276398330753 0.0408014726647365"
        rpy="0 0 0" />
      <mass
        value="0.673093868047935" />
      <inertia
        ixx="0.00186267936390827"
        ixy="-2.53444357200988E-05"
        ixz="-1.00048251014986E-05"
        iyy="0.00186267887714362"
        iyz="1.00057019988607E-05"
        izz="0.00250132222623779" />
    </inertial>
    <visual>
      <origin
        xyz="0 0 0"
        rpy="0 0 0" />
      <geometry>
        <mesh
          filename="package://bartender_description/meshes/base_link.STL" />
      </geometry>
      <material
        name="">
        <color
          rgba="0.101960784313725 0.101960784313725 0.101960784313725 1" />
      </material>
    </visual>
    <collision>
      <origin
        xyz="0 0 0"
        rpy="0 0 0" />
      <geometry>
        <mesh
          filename="package://bartender_description/meshes/base_link.STL" />
      </geometry>
    </collision>
  </link>
  <link
    name="Axis_1_link">
    <inertial>
      <origin
        xyz="-0.00365030561354215 -0.00081644827161792 -0.0729573734266458"
        rpy="0 0 0" />
      <mass
        value="1.82910817949668" />
      <inertia
        ixx="0.00567125702134137"
        ixy="6.72061455724579E-07"
        ixz="-0.00185865951164999"
        iyy="0.00733320048582221"
        iyz="-2.36962037644279E-05"
        izz="0.00583823394782265" />
    </inertial>
    <visual>
      <origin
        xyz="0 0 0"
        rpy="0 0 0" />
      <geometry>
        <mesh
          filename="package://bartender_description/meshes/Axis_1_link.STL" />
      </geometry>
      <material
        name="">
        <color
          rgba="0.792156862745098 0.819607843137255 0.933333333333333 1" />
      </material>
    </visual>
    <collision>
      <origin
        xyz="0 0 0"
        rpy="0 0 0" />
      <geometry>
        <mesh
          filename="package://bartender_description/meshes/Axis_1_link.STL" />
      </geometry>
    </collision>
  </link>
  <joint
    name="Axis_1_joint"
    type="revolute">
    <origin
      xyz="0 0 0.1016"
      rpy="-3.1416 0 3.1416" />
    <parent
      link="base_link" />
    <child
      link="Axis_1_link" />
    <axis
      xyz="0 0 1" />
    <limit
      lower="-3.14"
      upper="3.14"
      effort="0"
      velocity="0" />
  </joint>
  <link
    name="Axis_2_link">
    <inertial>
      <origin
        xyz="0.142947778762669 -0.000832462594946848 -0.0823797300358175"
        rpy="0 0 0" />
      <mass
        value="1.04847679276997" />
      <inertia
        ixx="0.00336606227972046"
        ixy="-2.21851955253561E-06"
        ixz="-1.59816100449962E-06"
        iyy="0.0053628670952623"
        iyz="1.8784096230903E-07"
        izz="0.00418411304724945" />
    </inertial>
    <visual>
      <origin
        xyz="0 0 0"
        rpy="0 0 0" />
      <geometry>
        <mesh
          filename="package://bartender_description/meshes/Axis_2_link.STL" />
      </geometry>
      <material
        name="">
        <color
          rgba="0.792156862745098 0.819607843137255 0.933333333333333 1" />
      </material>
    </visual>
    <collision>
      <origin
        xyz="0 0 0"
        rpy="0 0 0" />
      <geometry>
        <mesh
          filename="package://bartender_description/meshes/Axis_2_link.STL" />
      </geometry>
    </collision>
  </link>
  <joint
    name="Axis_2_joint"
    type="revolute">
    <origin
      xyz="0.077929 2E-05 -0.1378"
      rpy="0 1.5708 0" />
    <parent
      link="Axis_1_link" />
    <child
      link="Axis_2_link" />
    <axis
      xyz="0 0 1" />
    <limit
      lower="-1.5707"
      upper="1.5707"
      effort="0"
      velocity="0" />
  </joint>
  <link
    name="Axis_3_link">
    <inertial>
      <origin
        xyz="0.109778391394139 -0.0541162776297606 0.0190455815546458"
        rpy="0 0 0" />
      <mass
        value="0.0558365041968776" />
      <inertia
        ixx="0.000202674310099132"
        ixy="1.89113994475659E-05"
        ixz="-7.62245472555291E-08"
        iyy="0.000188860188467748"
        iyz="6.63515329006779E-08"
        izz="0.000209784902039166" />
    </inertial>
    <visual>
      <origin
        xyz="0 0 0"
        rpy="0 0 0" />
      <geometry>
        <mesh
          filename="package://bartender_description/meshes/Axis_3_link.STL" />
      </geometry>
      <material
        name="">
        <color
          rgba="0.109803921568627 0.109803921568627 0.109803921568627 1" />
      </material>
    </visual>
    <collision>
      <origin
        xyz="0 0 0"
        rpy="0 0 0" />
      <geometry>
        <mesh
          filename="package://bartender_description/meshes/Axis_3_link.STL" />
      </geometry>
    </collision>
  </link>
  <joint
    name="Axis_3_joint"
    type="revolute">
    <origin
      xyz="0.45724 -1.27E-05 -0.058371"
      rpy="-3.1416 0 1.5708" />
    <parent
      link="Axis_2_link" />
    <child
      link="Axis_3_link" />
    <axis
      xyz="0 0 1" />
    <limit
      lower="0"
      upper="2.09"
      effort="0"
      velocity="0" />
  </joint>
  <link
    name="Axis_4_link">
    <inertial>
      <origin
        xyz="-0.00128059595111962 1.4260263747623E-07 -0.0863046535214361"
        rpy="0 0 0" />
      <mass
        value="0.843880324194983" />
      <inertia
        ixx="0.00206181193490402"
        ixy="-1.04458522620057E-08"
        ixz="-8.89653836152743E-06"
        iyy="0.00176775660419444"
        iyz="-5.08426293610359E-09"
        izz="0.000718343307608655" />
    </inertial>
    <visual>
      <origin
        xyz="0 0 0"
        rpy="0 0 0" />
      <geometry>
        <mesh
          filename="package://bartender_description/meshes/Axis_4_link.STL" />
      </geometry>
      <material
        name="">
        <color
          rgba="0.792156862745098 0.819607843137255 0.933333333333333 1" />
      </material>
    </visual>
    <collision>
      <origin
        xyz="0 0 0"
        rpy="0 0 0" />
      <geometry>
        <mesh
          filename="package://bartender_description/meshes/Axis_4_link.STL" />
      </geometry>
    </collision>
  </link>
  <joint
    name="Axis_4_joint"
    type="revolute">
    <origin
      xyz="0.1630924711265 -0.0889905536771165 0.0190500000000004"
      rpy="-2.18798771833526 -1.57079630572147 1.65009985822568" />
    <parent
      link="Axis_3_link" />
    <child
      link="Axis_4_link" />
    <axis
      xyz="0 0 1" />
    <limit
      lower="-3.14"
      upper="3.14"
      effort="0"
      velocity="0" />
  </joint>
  <link
    name="Axis_5_link">
    <inertial>
      <origin
        xyz="-5.26379506573527E-05 -0.0015008205350327 -0.0166488984204937"
        rpy="0 0 0" />
      <mass
        value="0.0660564110907996" />
      <inertia
        ixx="1.95350797860467E-05"
        ixy="1.18768904859335E-07"
        ixz="1.55498377442463E-08"
        iyy="2.19364588424559E-05"
        iyz="-2.30452001894283E-07"
        izz="1.55853779323991E-05" />
    </inertial>
    <visual>
      <origin
        xyz="0 0 0"
        rpy="0 0 0" />
      <geometry>
        <mesh
          filename="package://bartender_description/meshes/Axis_5_link.STL" />
      </geometry>
      <material
        name="">
        <color
          rgba="0.752941176470588 0.752941176470588 0.752941176470588 1" />
      </material>
    </visual>
    <collision>
      <origin
        xyz="0 0 0"
        rpy="0 0 0" />
      <geometry>
        <mesh
          filename="package://bartender_description/meshes/Axis_5_link.STL" />
      </geometry>
    </collision>
  </link>
  <joint
    name="Axis_5_joint"
    type="revolute">
    <origin
      xyz="-0.0173250000739991 0 -0.196235319999999"
      rpy="-1.5707963267949 0 1.5707963267949" />
    <parent
      link="Axis_4_link" />
    <child
      link="Axis_5_link" />
    <axis
      xyz="0 0 -1" />
    <limit
      lower="-1.5707"
      upper="1.5707"
      effort="0"
      velocity="0" />
  </joint>
  <link
    name="Axis_6_link">
    <inertial>
      <origin
        xyz="0.00836903076162254 0.0114497288046549 -0.0324592423695391"
        rpy="0 0 0" />
      <mass
        value="0.133229676705801" />
      <inertia
        ixx="6.86937240933595E-05"
        ixy="-1.97590476823944E-07"
        ixz="3.87297691765862E-06"
        iyy="0.000104559847181407"
        iyz="-5.90555684906266E-07"
        izz="0.000109882606466749" />
    </inertial>
    <visual>
      <origin
        xyz="0 0 0"
        rpy="0 0 0" />
      <geometry>
        <mesh
          filename="package://bartender_description/meshes/Axis_6_link.STL" />
      </geometry>
      <material
        name="">
        <color
          rgba="0.792156862745098 0.819607843137255 0.933333333333333 1" />
      </material>
    </visual>
    <collision>
      <origin
        xyz="0 0 0"
        rpy="0 0 0" />
      <geometry>
        <mesh
          filename="package://bartender_description/meshes/Axis_6_link.STL" />
      </geometry>
    </collision>
  </link>
  <joint
    name="Axis_6_joint"
    type="revolute">
    <origin
      xyz="0 0.0170000000000001 -0.021"
      rpy="1.5707963267949 1.5707963267949 0" />
    <parent
      link="Axis_5_link" />
    <child
      link="Axis_6_link" />
    <axis
      xyz="0 0 -1" />
    <limit
      lower="-3.14"
      upper="3.14"
      effort="0"
      velocity="0" />
  </joint>
</robot>