<?xml version="1.0" encoding="utf-8"?>
<!-- This URDF was automatically created by SolidWorks to URDF Exporter! Originally created by Stephen Brawner (brawner@gmail.com) 
     Commit Version: 1.5.1-0-g916b5db  Build Version: 1.5.7152.31018
     For more information, please see http://wiki.ros.org/sw_urdf_exporter -->
<robot
  name="bartender_description">
  <link
    name="base_link">
    <inertial>
      <origin
        xyz="-0.0609843868522775 -0.000348754231501491 -0.000443834914845564"
        rpy="0 0 0" />
      <mass
        value="0.676504739832433" />
      <inertia
        ixx="0.00251563159843823"
        ixy="-4.10339231925769E-06"
        ixz="-5.22187544994779E-06"
        iyy="0.00187014587164591"
        iyz="1.77192420719245E-05"
        izz="0.00187878058701035" />
    </inertial>
    <visual>
      <origin
        xyz="0 0 0"
        rpy="0 0 0" />
      <geometry>
        <mesh
          filename="package://bartender_description/meshes/base_link.STL" />
      </geometry>
      <material
        name="">
        <color
          rgba="0.101960784313725 0.101960784313725 0.101960784313725 1" />
      </material>
    </visual>
    <collision>
      <origin
        xyz="0 0 0"
        rpy="0 0 0" />
      <geometry>
        <mesh
          filename="package://bartender_description/meshes/base_link.STL" />
      </geometry>
    </collision>
  </link>
  <link
    name="Axis_1_link">
    <inertial>
      <origin
        xyz="0.0729560782852224 0.00082145663795552 0.00365068847641203"
        rpy="0 0 0" />
      <mass
        value="1.82885153997862" />
      <inertia
        ixx="0.00583759098719345"
        ixy="-2.38375261062292E-05"
        ixz="-0.00185877754846389"
        iyy="0.00733296734166156"
        iyz="7.78779279141757E-07"
        izz="0.00567092540646294" />
    </inertial>
    <visual>
      <origin
        xyz="0 0 0"
        rpy="0 0 0" />
      <geometry>
        <mesh
          filename="package://bartender_description/meshes/Axis_1_link.STL" />
      </geometry>
      <material
        name="">
        <color
          rgba="0.792156862745098 0.819607843137255 0.933333333333333 1" />
      </material>
    </visual>
    <collision>
      <origin
        xyz="0 0 0"
        rpy="0 0 0" />
      <geometry>
        <mesh
          filename="package://bartender_description/meshes/Axis_1_link.STL" />
      </geometry>
    </collision>
  </link>
  <joint
    name="Axis_1_joint"
    type="revolute">
    <origin
      xyz="0 0 0"
      rpy="0 0 0" />
    <parent
      link="base_link" />
    <child
      link="Axis_1_link" />
    <axis
      xyz="1 0 0" />
    <limit
      lower="-3.14"
      upper="3.14"
      effort="0"
      velocity="0" />
  </joint>
  <link
    name="Axis_2_link">
    <inertial>
      <origin
        xyz="-0.000820402232070361 0.0709889462648658 -0.0801008440347226"
        rpy="0 0 0" />
      <mass
        value="0.759061020793129" />
      <inertia
        ixx="0.00191469729323514"
        ixy="1.33484797139316E-07"
        ixz="5.2513920355149E-06"
        iyy="0.00151285567633713"
        iyz="-1.37236304033981E-06"
        izz="0.00174858862744118" />
    </inertial>
    <visual>
      <origin
        xyz="0 0 0"
        rpy="0 0 0" />
      <geometry>
        <mesh
          filename="package://bartender_description/meshes/Axis_2_link.STL" />
      </geometry>
      <material
        name="">
        <color
          rgba="0.792156862745098 0.819607843137255 0.933333333333333 1" />
      </material>
    </visual>
    <collision>
      <origin
        xyz="0 0 0"
        rpy="0 0 0" />
      <geometry>
        <mesh
          filename="package://bartender_description/meshes/Axis_2_link.STL" />
      </geometry>
    </collision>
  </link>
  <joint
    name="Axis_2_joint"
    type="revolute">
    <origin
      xyz="0.137795000103731 0 -0.0646429999999996"
      rpy="1.5707963267949 0 -1.04721351667053" />
    <parent
      link="Axis_1_link" />
    <child
      link="Axis_2_link" />
    <axis
      xyz="0 -1 0" />
    <limit
      lower="-0.69813"
      upper="1.7453"
      effort="0"
      velocity="0" />
  </joint>
  <link
    name="Axis_3_link">
    <inertial>
      <origin
        xyz="0.00283138679401818 -0.064135102771337 -0.0449191066131345"
        rpy="0 0 0" />
      <mass
        value="3.93214824777397" />
      <inertia
        ixx="0.0107226479079192"
        ixy="5.57815363377064E-09"
        ixz="-8.8193686837861E-05"
        iyy="0.00908669621568845"
        iyz="-3.47553481805894E-09"
        izz="0.010668866355472" />
    </inertial>
    <visual>
      <origin
        xyz="0 0 0"
        rpy="0 0 0" />
      <geometry>
        <mesh
          filename="package://bartender_description/meshes/Axis_3_link.STL" />
      </geometry>
      <material
        name="">
        <color
          rgba="0.792156862745098 0.819607843137255 0.933333333333333 1" />
      </material>
    </visual>
    <collision>
      <origin
        xyz="0 0 0"
        rpy="0 0 0" />
      <geometry>
        <mesh
          filename="package://bartender_description/meshes/Axis_3_link.STL" />
      </geometry>
    </collision>
  </link>
  <joint
    name="Axis_3_joint"
    type="revolute">
    <origin
      xyz="0 0 -0.457236661597999"
      rpy="-3.14159265358979 1.02839101554935 0" />
    <parent
      link="Axis_2_link" />
    <child
      link="Axis_3_link" />
    <axis
      xyz="0 1 0" />
    <limit
      lower="-0.87267"
      upper="0.17453"
      effort="0"
      velocity="0" />
  </joint>
  <link
    name="Axis_4_link">
    <inertial>
      <origin
        xyz="-0.0006976248893516 3.7447942324853E-07 0.0675175256535027"
        rpy="0 0 0" />
      <mass
        value="0.856489560610893" />
      <inertia
        ixx="0.00206818926397165"
        ixy="1.1985081554126E-08"
        ixz="8.66736183072786E-06"
        iyy="0.00177128098918653"
        iyz="-3.46924973761132E-09"
        izz="0.000721510758935695" />
    </inertial>
    <visual>
      <origin
        xyz="0 0 0"
        rpy="0 0 0" />
      <geometry>
        <mesh
          filename="package://bartender_description/meshes/Axis_4_link.STL" />
      </geometry>
      <material
        name="">
        <color
          rgba="0.792156862745098 0.819607843137255 0.933333333333333 1" />
      </material>
    </visual>
    <collision>
      <origin
        xyz="0 0 0"
        rpy="0 0 0" />
      <geometry>
        <mesh
          filename="package://bartender_description/meshes/Axis_4_link.STL" />
      </geometry>
    </collision>
  </link>
  <joint
    name="Axis_4_joint"
    type="revolute">
    <origin
      xyz="0.00833174747644083 -0.0641349999999993 -0.2046669392351"
      rpy="-3.1227709049678 -0.000168316999353158 -1.56185493455129" />
    <parent
      link="Axis_3_link" />
    <child
      link="Axis_4_link" />
    <axis
      xyz="0 0 -1" />
    <limit
      lower="-3.14"
      upper="3.14"
      effort="0"
      velocity="0" />
  </joint>
  <link
    name="Axis_5_link">
    <inertial>
      <origin
        xyz="0.218657056548553 -2.50836127830834E-05 -0.00161150647560715"
        rpy="0 0 0" />
      <mass
        value="0.0617503556433187" />
      <inertia
        ixx="1.46766827950709E-05"
        ixy="-6.82357221265635E-09"
        ixz="2.1755578356245E-07"
        iyy="1.87257088507101E-05"
        iyz="-6.03273354138711E-08"
        izz="2.11045050684811E-05" />
    </inertial>
    <visual>
      <origin
        xyz="0 0 0"
        rpy="0 0 0" />
      <geometry>
        <mesh
          filename="package://bartender_description/meshes/Axis_5_link.STL" />
      </geometry>
      <material
        name="">
        <color
          rgba="0.752941176470588 0.752941176470588 0.752941176470588 1" />
      </material>
    </visual>
    <collision>
      <origin
        xyz="0 0 0"
        rpy="0 0 0" />
      <geometry>
        <mesh
          filename="package://bartender_description/meshes/Axis_5_link.STL" />
      </geometry>
    </collision>
  </link>
  <joint
    name="Axis_5_joint"
    type="revolute">
    <origin
      xyz="-0.217825000000417 0 0.17718532"
      rpy="0 0 0" />
    <parent
      link="Axis_4_link" />
    <child
      link="Axis_5_link" />
    <axis
      xyz="1 0 0" />
    <limit
      lower="-1.5707"
      upper="1.5707"
      effort="0"
      velocity="0" />
  </joint>
  <link
    name="Axis_6_link">
    <inertial>
      <origin
        xyz="1.11022302462516E-16 -2.22044604925031E-16 0.0236537500000001"
        rpy="0 0 0" />
      <mass
        value="0.00888214913786918" />
      <inertia
        ixx="1.99606171787005E-06"
        ixy="-4.2351647362715E-22"
        ixz="-3.09696421339854E-21"
        iyy="1.99606171787004E-06"
        iyz="7.30565917006834E-21"
        izz="6.79082464223824E-07" />
    </inertial>
    <visual>
      <origin
        xyz="0 0 0"
        rpy="0 0 0" />
      <geometry>
        <mesh
          filename="package://bartender_description/meshes/Axis_6_link.STL" />
      </geometry>
      <material
        name="">
        <color
          rgba="0.792156862745098 0.819607843137255 0.933333333333333 1" />
      </material>
    </visual>
    <collision>
      <origin
        xyz="0 0 0"
        rpy="0 0 0" />
      <geometry>
        <mesh
          filename="package://bartender_description/meshes/Axis_6_link.STL" />
      </geometry>
    </collision>
  </link>
  <joint
    name="Axis_6_joint"
    type="revolute">
    <origin
      xyz="0.2205 0 0.0283074999999999"
      rpy="3.14159265358979 0 -0.137857887972684" />
    <parent
      link="Axis_5_link" />
    <child
      link="Axis_6_link" />
    <axis
      xyz="0 0 -1" />
    <limit
      lower="-3.14"
      upper="3.14"
      effort="0"
      velocity="0" />
  </joint>
</robot>